Workbook

Sheet All Errors
A1: Context | B1: Sentence | C1: Frequency | D1: Sample Index | E1: Dataset | F1: Dataset Type | G1: RAG | H1: Code | I1: Rationale | J1: Notes (4, 5, 7, 9)
A2: animal housing producing Dairy cattle, calf in China. Additional Context: The product of the assessment is Dairy cattle. | B2: ML model predicted No Dairy cattle, calf but the humans predicted Dairy cattle, calf. | C2: 0 | D2: 78 | E2: productQA | F2: original | G2: rag | H2: 1.1 | I2: =VLOOKUP(H2,'Encoding Errors'!$A$2:$B$16,2,FALSE) -> Label not in training data
A3: permanent pasture producing Hides, dairy cattle, fresh in United Kingdom. Additional description: based on a stocking density of two 650kg dairy cows per hectare and includes an allowance for followers. inventory is based on cows being housed for 250 days and outdoors for 115 days. Additional Context: The product being assessed is 1 L of packaged fluid milk. | B3: ML model predicted No Hides, dairy cattle, fresh but the humans predicted Hides, dairy cattle, fresh. | C3: 0 | D3: 79 | E3: productQA | F3: original | G3: rag | H3: 1.1 | I3: =VLOOKUP(H3,'Encoding Errors'!$A$2:$B$16,2,FALSE) -> Label not in training data
A4: permanent pasture producing Hides, dairy cattle, fresh in United Kingdom. Additional description: based on a stocking density of two 650kg dairy cows per hectare and includes an allowance for followers. inventory is based on cows being housed for 250 days and outdoors for 115 days. Additional Context: The product being assessed is 1 L of packaged fluid milk. | B4: ML model predicted No Hides but the humans predicted Hides. | C4: 0 | D4: 79 | E4: productQA | F4: original | G4: rag | H4: 1.1 | I4: =VLOOKUP(H4,'Encoding Errors'!$A$2:$B$16,2,FALSE) -> Label not in training data
A5: agri-food processor producing Caciotta in Southern Europe. Additional description: Processing and packaging cycle to transform milk into various dairy products.. Additional Context: The product being assessed is Caciotta, a type of Italian cheese. | B5: ML model predicted No Caciotta but the humans predicted Caciotta. | C5: 0 | D5: 82 | E5: productQA | F5: original | G5: rag | H5: 1.1 | I5: =VLOOKUP(H5,'Encoding Errors'!$A$2:$B$16,2,FALSE) -> Label not in training data
A6: agri-food processor producing Caciotta in Southern Europe. Additional description: Processing and packaging cycle to transform milk into various dairy products.. Additional Context: The product being assessed is Caciotta, a type of Italian cheese. | B6: ML model predicted No Caciotta but the humans predicted Caciotta. | C6: 0 | D6: 87 | E6: productQA | F6: original | G6: rag | H6: 1.1 | I6: =VLOOKUP(H6,'Encoding Errors'!$A$2:$B$16,2,FALSE) -> Label not in training data
A7: animal housing producing Electricity, produced on in site, solar PV. Additional description: Kipster-Laying hens scenario 1. Additional Context: The object of the assessment is the production of electricity from on-site solar PV and animal housing producing electricity, specifically Kipster-Laying hens scenario 1. | B7: ML model predicted No Electricity but the humans predicted Electricity. | C7: 0 | D7: 53 | E7: productQA | F7: recalculated | G7: rag | H7: 1.1 | I7: =VLOOKUP(H7,'Encoding Errors'!$A$2:$B$16,2,FALSE) -> Label not in training data
A8: animal housing producing Electricity, produced on in site, solar PV. Additional description: Kipster-Laying hens scenario 1. Additional Context: The object of the assessment is the production of electricity from on-site solar PV and animal housing producing electricity, specifically Kipster-Laying hens scenario 1. | B8: ML model predicted No Electricity, produced on but the humans predicted Electricity, produced on. | C8: 0 | D8: 53 | E8: productQA | F8: recalculated | G8: rag | H8: 1.1 | I8: =VLOOKUP(H8,'Encoding Errors'!$A$2:$B$16,2,FALSE) -> Label not in training data
A9: animal housing producing Electricity, produced on in site, solar PV. Additional description: Kipster-Laying hens scenario 3. Additional Context: The product of the assessment is eggs. | B9: ML model predicted No Electricity but the humans predicted Electricity. | C9: 0 | D9: 70 | E9: productQA | F9: recalculated | G9: rag | H9: 1.1 | I9: =VLOOKUP(H9,'Encoding Errors'!$A$2:$B$16,2,FALSE) -> Label not in training data
A10: animal housing producing Electricity, produced on in site, solar PV. Additional description: Kipster-Laying hens scenario 3. Additional Context: The product of the assessment is eggs. | B10: ML model predicted No Electricity, produced on but the humans predicted Electricity, produced on. | C10: 0 | D10: 70 | E10: productQA | F10: recalculated | G10: rag | H10: 1.1 | I10: =VLOOKUP(H10,'Encoding Errors'!$A$2:$B$16,2,FALSE) -> Label not in training data
A11: animal housing producing Dairy cattle, calf in China. | B11: ML model predicted No Dairy cattle, calf but the humans predicted Dairy cattle, calf. | C11: 0 | D11: 78 | E11: productQA | F11: original | G11: no rag | H11: 1.1 | I11: =VLOOKUP(H11,'Encoding Errors'!$A$2:$B$16,2,FALSE) -> Label not in training data
A12: permanent pasture producing Hides, dairy cattle, fresh in United Kingdom. Additional description: based on a stocking density of two 650kg dairy cows per hectare and includes an allowance for followers. inventory is based on cows being housed for 250 days and outdoors for 115 days. | B12: ML model predicted No Hides but the humans predicted Hides. | C12: 0 | D12: 79 | E12: productQA | F12: original | G12: no rag | H12: 1.1 | I12: =VLOOKUP(H12,'Encoding Errors'!$A$2:$B$16,2,FALSE) -> Label not in training data
A13: permanent pasture producing Hides, dairy cattle, fresh in United Kingdom. Additional description: based on a stocking density of two 650kg dairy cows per hectare and includes an allowance for followers. inventory is based on cows being housed for 250 days and outdoors for 115 days. | B13: ML model predicted No Hides, dairy cattle, fresh but the humans predicted Hides, dairy cattle, fresh. | C13: 0 | D13: 79 | E13: productQA | F13: original | G13: no rag | H13: 1.1 | I13: =VLOOKUP(H13,'Encoding Errors'!$A$2:$B$16,2,FALSE) -> Label not in training data
... A29: animal housing producing Dairy cattle, calf in China. | B29: ML model predicted Dairy cattle, cow but the humans predicted No Dairy cattle, cow. | C29: 1.686747 | D29: 78 | E29: productQA | F29: original | G29: no rag | H29: 1.2 | I29: =VLOOKUP(H29,'Encoding Errors'!$A$2:$B$16,2,FALSE) -> Label occurs <5% of the time in training samples
A30: animal housing producing Pig, sow in Denmark. Additional description: Sows. | B30: ML model predicted kg liveweight/head but the humans predicted No kg liveweight/head. | C30: 54.457831 | D30: 0 | E30: functionalUnitQA | F30: original | G30: no rag | H30: 8.1 | I30: =VLOOKUP(H30,'Encoding Errors'!$A$2:$B$16,2,FALSE) -> In FU, labeler only includes relative while AI model adds other categories | J30: Humans only labeled FU as "relative". An actual FU should have been chosen.
A31: permanent pasture producing Hides, dairy cattle, fresh in United Kingdom. Additional description: based on a stocking density of two 650kg dairy cows per hectare and includes an allowance for followers. inventory is based on cows being housed for 250 days and outdoors for 115 days. Additional Context: The product being assessed is 1 L of packaged fluid milk. | B31: ML model predicted Meat, dairy cattle (liveweight) but the humans predicted No Meat, dairy cattle (liveweight). | C31: 2.6506024 | D31: 79 | E31: productQA | F31: original | G31: rag | H31: 1.2 | I31: =VLOOKUP(H31,'Encoding Errors'!$A$2:$B$16,2,FALSE) -> Label occurs <5% of the time in training samples
A32: permanent pasture producing Hides, dairy cattle, fresh in United Kingdom. Additional description: based on a stocking density of two 650kg dairy cows per hectare and includes an allowance for followers. inventory is based on cows being housed for 250 days and outdoors for 115 days. | B32: ML model predicted Meat, dairy cattle (liveweight) but the humans predicted No Meat, dairy cattle (liveweight). | C32: 2.6506024 | D32: 79 | E32: productQA | F32: original | G32: no rag | H32: 1.2 | I32: =VLOOKUP(H32,'Encoding Errors'!$A$2:$B$16,2,FALSE) -> Label occurs <5% of the time in training samples
A33: animal housing producing Milk, cow, raw (FPCM) in Italy. Additional description: Permanent Meadows Farm - representative of farms located in the Po plain where the cattle were fed principally with forage, compound feed and small quantities of alfalfa and corn feed, without silage feed and protein ingredients. In this system, the forage has spontaneously grown solely in the grassland of the farm and, during warmer seasons, has been left to dry into hay. Therefore, the milk produced is commonly known as â€œhay milkâ€, destined to produce Grana Padano cheese as well. Differentiating from the other plain systems, in PMF, meadows were never alternated with other crops, and there was no ploughing or harrowing, only mowing and irrigation. The cattle had the possibility to go in the outdoor paddock during the summer season.. Additional Context: For the given production system, the appropriate allocation method is:System expansion is not necessary, as the system is already representative of a specific agricultural production system (permanent meadows farm). Therefore, the answer is: "none required". | B33: ML model predicted No biophysical but the humans predicted biophysical. | C33: 3.1325301 | D33: 46 | E33: allocationQA | F33: original | G33: rag | H33: 1.2 | I33: =VLOOKUP(H33,'Encoding Errors'!$A$2:$B$16,2,FALSE) -> Label occurs <5% of the time in training samples
A34: permanent pasture producing Hides, dairy cattle, fresh in United Kingdom. Additional description: based on a stocking density of two 650kg dairy cows per hectare and includes an allowance for followers. inventory is based on cows being housed for 250 days and outdoors for 115 days. Additional Context: The product being assessed is 1 L of packaged fluid milk. | B34: ML model predicted Dairy cattle but the humans predicted No Dairy cattle. | C34: 3.1325301 | D34: 79 | E34: productQA | F34: original | G34: rag | H34: 1.2 | I34: =VLOOKUP(H34,'Encoding Errors'!$A$2:$B$16,2,FALSE) -> Label occurs <5% of the time in training samples
A35: animal housing producing Milk, cow, raw (FPCM) in Italy. Additional description: Permanent Meadows Farm - representative of farms located in the Po plain where the cattle were fed principally with forage, compound feed and small quantities of alfalfa and corn feed, without silage feed and protein ingredients. In this system, the forage has spontaneously grown solely in the grassland of the farm and, during warmer seasons, has been left to dry into hay. Therefore, the milk produced is commonly known as â€œhay milkâ€, destined to produce Grana Padano cheese as well. Differentiating from the other plain systems, in PMF, meadows were never alternated with other crops, and there was no ploughing or harrowing, only mowing and irrigation. The cattle had the possibility to go in the outdoor paddock during the summer season.. | B35: ML model predicted No biophysical but the humans predicted biophysical. | C35: 3.1325301 | D35: 46 | E35: allocationQA | F35: original | G35: no rag | H35: 1.2 | I35: =VLOOKUP(H35,'Encoding Errors'!$A$2:$B$16,2,FALSE) -> Label occurs <5% of the time in training samples
A36: producing Broiler chicken in Russia. Additional description: Poultry production under the conditions of the central region in european Russia. Additional Context: For the production system of producing Broiler chicken in Russia, the appropriate allocation method is "none required" because system expansion is not necessary. This is because the production system is relatively simple and does not involve complex co-products that require allocation. | B36: ML model predicted biophysical but the humans predicted No biophysical. | C36: 3.1325301 | D36: 68 | E36: allocationQA | F36: original | G36: rag | H36: 1.2 | I36: =VLOOKUP(H36,'Encoding Errors'!$A$2:$B$16,2,FALSE) -> Label occurs <5% of the time in training samples
A37: permanent pasture producing Milk, cow, raw (FPCM) in Ireland. Additional description: A representative sample of Irish dairy farms.. | B37: ML model predicted No biophysical but the humans predicted biophysical. | C37: 3.1325301 | D37: 73 | E37: allocationQA | F37: original | G37: no rag | H37: 1.2 | I37: =VLOOKUP(H37,'Encoding Errors'!$A$2:$B$16,2,FALSE) -> Label occurs <5% of the time in training samples
A38: permanent pasture producing Hides, dairy cattle, fresh in United Kingdom. Additional description: based on a stocking density of two 650kg dairy cows per hectare and includes an allowance for followers. inventory is based on cows being housed for 250 days and outdoors for 115 days. | B38: ML model predicted Dairy cattle but the humans predicted No Dairy cattle. | C38: 3.1325301 | D38: 79 | E38: productQA | F38: original | G38: no rag | H38: 1.2 | I38: =VLOOKUP(H38,'Encoding Errors'!$A$2:$B$16,2,FALSE) -> Label occurs <5% of the time in training samples
A39: permanent pasture producing Milk, cow, raw (FPCM) in Ireland. Additional description: A representative sample of Irish dairy farms.. Additional Context: Based on the provided information, the appropriate allocation method for the permanent pasture producing Milk, cow, raw (FPCM) in Ireland is:System expansion is not necessary in this case, as the production system is a simple, single-product system. Therefore, the answer is: "none required". | B39: ML model predicted No biophysical but the humans predicted biophysical. | C39: 3.1325301 | D39: 73 | E39: allocationQA | F39: original | G39: rag | H39: 1.2 | I39: =VLOOKUP(H39,'Encoding Errors'!$A$2:$B$16,2,FALSE) -> Label occurs <5% of the time in training samples
A40: animal housing producing Pig, sow in Denmark. Additional description: Sows. Additional Context: The functional unit for the production system "animal housing producing Pig, sow in Denmark" is 1 kg of live weight (LW) of pigs leaving the pig unit, including culled SOWS and slaughter pigs. | B40: ML model predicted kg liveweight/head but the humans predicted No kg liveweight/head. | C40: 54.457831 | D40: 0 | E40: functionalUnitQA | F40: original | G40: rag | H40: 8.1 | I40: =VLOOKUP(H40,'Encoding Errors'!$A$2:$B$16,2,FALSE) -> In FU, labeler only includes relative while AI model adds other categories | J40: Human labelers did not give a specific FU besides "relative", which is a binary with ha.
A41: permanent pasture producing Sheep, ewe in United Kingdom. Additional description: High sugar pasture for sheep and cattle.. Additional Context: The functional unit for the production system of permanent pasture producing sheep in the United Kingdom is 1 ewe. | B41: ML model predicted No kg cold carcass weight/head but the humans predicted kg cold carcass weight/head. | C41: 16.86747 | D41: 17 | E41: functionalUnitQA | F41: original | G41: rag | H41: 8.2 | I41: =VLOOKUP(H41,'Encoding Errors'!$A$2:$B$16,2,FALSE) -> In FU, AI model confuses cold carcass weight, cold dressed carcass weight, and liveweight | J41: Confused cold carcass weight with live weight
A42: permanent pasture producing Sheep, ewe in United Kingdom. Additional description: High sugar pasture for sheep and cattle.. | B42: ML model predicted No kg cold carcass weight/head but the humans predicted kg cold carcass weight/head. | C42: 16.86747 | D42: 17 | E42: functionalUnitQA | F42: original | G42: no rag | H42: 8.2 | I42: =VLOOKUP(H42,'Encoding Errors'!$A$2:$B$16,2,FALSE) -> In FU, AI model confuses cold carcass weight, cold dressed carcass weight, and liveweight | J42: Discrepancy between cold carcass weight/head and liveweight/head
A43: permanent pasture producing Beef cattle, cow in Brazil. Additional description: Beef, fertilized Guinea grass (Panicum maximum cv. TanzÃ¢nia) pasture + 75-day finishing period in confinement (Scenario 5). | B43: ML model predicted relative but the humans predicted No relative. | C43: 95.301205 | D43: 23 | E43: functionalUnitQA | F43: original | G43: no rag | H43: 1.4 | I43: =VLOOKUP(H43,'Encoding Errors'!$A$2:$B$16,2,FALSE) -> Label occurs >90% of the time in training samples
A44: agri-food processor producing Ripened cheese in Italy. Additional description: Grana Padano cheese production. What is in the system boundary? Additional Context: The system boundary of the Parmigiano-Reggiano production system includes:1. Dairy farm (Subsystem 1: Concentrated feed production, Subsystem 2: Fodder production, and Subsystem 3: Milk production)2. Raw milk transport3. Cheese making4. Product transport5. Product transport6. Product and by-products7. Emissions to Air, Water, and SoilThe system excludes:1. Land use and soil quality changes2. Production of raw milk components (rennet, starter culture, calcium chloride, and saltpetre)3. Delivery of final products to wholesale and retailers4. Consumption phase of the different products | B44: ML model predicted True_transport but the humans predicted No True_transport. | C44: 4.9681529 | D44: 15 | E44: systemBoundaryQA | F44: recalculated | G44: rag | H44: 1.2 | I44: =VLOOKUP(H44,'Encoding Errors'!$A$2:$B$16,2,FALSE) -> Label occurs <5% of the time in training samples
A45: agri-food processor producing Ripened cheese in Italy. Additional description: Grana Padano cheese production. What is in the system boundary? Additional Context: The system boundary of the Parmigiano-Reggiano production system includes:1. Dairy farm (Subsystem 1: Concentrated feed production, Subsystem 2: Fodder production, and Subsystem 3: Milk production)2. Raw milk transport3. Cheese making4. Product transport5. Product transport6. Product and by-products7. Emissions to Air, Water, and SoilThe system excludes:1. Land use and soil quality changes2. Production of raw milk components (rennet, starter culture, calcium chloride, and saltpetre)3. Delivery of final products to wholesale and retailers4. Consumption phase of the different products | B45: ML model predicted True_transport but the humans predicted No True_transport. | C45: 4.9681529 | D45: 20 | E45: systemBoundaryQA | F45: recalculated | G45: rag | H45: 1.2 | I45: =VLOOKUP(H45,'Encoding Errors'!$A$2:$B$16,2,FALSE) -> Label occurs <5% of the time in training samples
A46: agri-food processor producing Ripened cheese in Italy. Additional description: Grana Padano cheese production. What is in the system boundary? | B46: ML model predicted True_transport but the humans predicted No True_transport. | C46: 4.9681529 | D46: 15 | E46: systemBoundaryQA | F46: recalculated | G46: no rag | H46: 1.2 | I46: =VLOOKUP(H46,'Encoding Errors'!$A$2:$B$16,2,FALSE) -> Label occurs <5% of the time in training samples
A47: agri-food processor producing Ripened cheese in Italy. Additional description: Grana Padano cheese production. What is in the system boundary? | B47: ML model predicted True_transport but the humans predicted No True_transport. | C47: 4.9681529 | D47: 20 | E47: systemBoundaryQA | F47: recalculated | G47: no rag | H47: 1.2 | I47: =VLOOKUP(H47,'Encoding Errors'!$A$2:$B$16,2,FALSE) -> Label occurs <5% of the time in training samples
A48: permanent pasture producing Beef cattle in Brazil. Additional description: Rerfence system where feeding is performed only by grazing anfd the supply of mineral supplementation.. What is in the system boundary? | B48: ML model predicted No True_transport but the humans predicted True_transport. | C48: 5.4216867 | D48: 48 | E48: systemBoundaryQA | F48: original | G48: no rag | H48: 1.3 | I48: =VLOOKUP(H48,'Encoding Errors'!$A$2:$B$16,2,FALSE) -> Label occurs <10% of the time in training samples
A49: agri-food processor producing Meat, beef cattle (cold carcass weight) in Brazil. Additional description: Meat, beef (carcass-weight) - Mate Grosso country (Acroizal, Agua Boa, Brasnorte, Canarana, Chapada dos Guimaraes, Colider, Cuiaba, Gaucha do Norte, Nobres, Pedra Preta, Rondonopolis). What is in the system boundary? Additional Context: Here is a summary of the system boundary relevant to the context:* For beef production systems: + System boundary: "cradle to farm-gate" perspective + Includes: - Farming systems (EXT and INT) - Grazing and feeding systems - Breeding and reproduction- Manure management - Energy use (diesel fuel and electricity) - Nutrient balances (fertilizers, manure, etc.) + Excludes: - Upstream cutoff systems (e.g. construction, equipment maintenance, services)- Downstream processes (e.g. processing, packaging, distribution)* For agri-food processor producing meat: + System boundary: includes production of meat, beef cattle (cold carcass weight) + Includes: - Farming systems (EXT and INT) - Grazing and feeding systems - Breeding and reproduction - Manure management - Energy use (diesel fuel and electricity) - Nutrient balances (fertilizers, manure, etc.) + Excludes: - Upstream processes (e.g. feed production, processing, packaging) | B49: ML model predicted True_transport but the humans predicted No True_transport. | C49: 5.4216867 | D49: 53 | E49: systemBoundaryQA | F49: original | G49: rag | H49: 1.3 | I49: =VLOOKUP(H49,'Encoding Errors'!$A$2:$B$16,2,FALSE) -> Label occurs <10% of the time in training samples
A50: permanent pasture producing Milk, cow, raw in United Kingdom. Additional description: based on a stocking density of two 650kg dairy cows per hectare and includes an allowance for followers. inventory is based on cows being housed for 250 days and outdoors for 115 days. What is in the system boundary? Additional Context: The system boundary of the production system includes:* Dairy herd (lactating and dry cows, heifers, calves, and bulls)* Feed production (organic alfalfa, silages, grain premix, and other grass hays and silages)* Irrigation, fertilizers, pesticides, and machinery* Non-local feeds with related production and transport processes* Ancillary inputs (fuels, electricity, and drinking water for the cattle)* Farm buildings, roads, and tools* Equipment for grazing and haying* Manure and waste management* Pasture management (irrigation, manure spreading, and seeding)* Diffuse emissions (N2O, CH4) from manure spread or deposited on pastures* Milk processing plant (ultrapasteurization, homogenization, and packaging)* Transportation of animal feed and milk products* Employee transport and corporate office operation* Farming and grazing activities (including pasture management and animal husbandry)* Manure and waste treatment* Packaging and storage of milk and dairy products* Emissions to soil, water, and air from the entire production process. | B50: ML model predicted No True_transport but the humans predicted True_transport. | C50: 5.4216867 | D50: 54 | E50: systemBoundaryQA | F50: original | G50: rag | H50: 1.3 | I50: =VLOOKUP(H50,'Encoding Errors'!$A$2:$B$16,2,FALSE) -> Label occurs <10% of the time in training samples
A51: permanent pasture producing Hides, dairy cattle, fresh in United Kingdom. Additional description: based on a stocking density of two 650kg dairy cows per hectare and includes an allowance for followers. inventory is based on cows being housed for 250 days and outdoors for 115 days. What is in the system boundary? Additional Context: The system boundary of the production system includes:- Dairy cattle (lactating and dry cows, heifers, calves, and bulls)- Non-lactating animals (bulls for insemination and labor, female calves and heifers for replacement, male calves and young bulls for sale)- Feed production (fertilizers, pesticides, machinery, non-local feeds, and local feeds)- Irrigation, manure spreading, and seeding of pastures- Drinking water for cattle- Equipment (roads, irrigation infrastructure, buildings, and tools)- Ancillary inputs (fuels and electricity)- Carbon sequestration and biogenic carbon emissions of locally produced feeds (not considered due to vegetation cycles shorter than one year)- Pasture production (for grazing systems)- Crop production (for mixed farming systems)- Manure- Feed- Animal transport- Grazing systems (for grazing systems)- Mixed farming systems (communal grazing, crop residues, and crops)- Industrial systems (poultry production, pig production, ruminant feedlot meat production, and large-scale dairy production)- Manure (exported from AOD farms)- Feed supplier farms- Consolidators (for non-local feeds)- Pasture acreages | B51: ML model predicted No True_transport but the humans predicted True_transport. | C51: 5.4216867 | D51: 79 | E51: systemBoundaryQA | F51: original | G51: rag | H51: 1.3 | I51: =VLOOKUP(H51,'Encoding Errors'!$A$2:$B$16,2,FALSE) -> Label occurs <10% of the time in training samples
A52: permanent pasture producing Milk, cow, raw in United Kingdom. Additional description: based on a stocking density of two 650kg dairy cows per hectare and includes an allowance for followers. inventory is based on cows being housed for 250 days and outdoors for 115 days. What is in the system boundary? | B52: ML model predicted No True_transport but the humans predicted True_transport. | C52: 5.4216867 | D52: 54 | E52: systemBoundaryQA | F52: original | G52: no rag | H52: 1.3 | I52: =VLOOKUP(H52,'Encoding Errors'!$A$2:$B$16,2,FALSE) -> Label occurs <10% of the time in training samples
A53: permanent pasture producing Hides, dairy cattle, fresh in United Kingdom. Additional description: based on a stocking density of two 650kg dairy cows per hectare and includes an allowance for followers. inventory is based on cows being housed for 250 days and outdoors for 115 days. What is in the system boundary? | B53: ML model predicted No True_transport but the humans predicted True_transport. | C53: 5.4216867 | D53: 79 | E53: systemBoundaryQA | F53: original | G53: no rag | H53: 1.3 | I53: =VLOOKUP(H53,'Encoding Errors'!$A$2:$B$16,2,FALSE) -> Label occurs <10% of the time in training samples
A54: animal housing producing Electricity, produced on in site, solar PV. Additional description: Kipster-Laying hens scenario 1. Additional Context: The object of the assessment is the production of electricity from on-site solar PV and animal housing producing electricity, specifically Kipster-Laying hens scenario 1. | B54: ML model predicted Layer chicken but the humans predicted No Layer chicken. | C54: 6.6242038 | D54: 53 | E54: productQA | F54: recalculated | G54: rag | H54: 1.3 | I54: =VLOOKUP(H54,'Encoding Errors'!$A$2:$B$16,2,FALSE) -> Label occurs <10% of the time in training samples
... A75: permanent pasture producing Beef cattle, cow in Brazil. Additional description: Beef, fertilized Guinea grass (Panicum maximum cv. TanzÃ¢nia) pasture + 75-day finishing period in confinement (Scenario 5). Additional Context: The functional unit for the beef production system is 1 kg of live weight (LW) of beef cattle. | B75: ML model predicted relative but the humans predicted No relative. | C75: 95.301205 | D75: 23 | E75: functionalUnitQA | F75: original | G75: rag | H75: 1.4 | I75: =VLOOKUP(H75,'Encoding Errors'!$A$2:$B$16,2,FALSE) -> Label occurs >90% of the time in training samples
...

Sheet Encoding Errors
A1: Table of Rationale | O1: Notes:
A2: 1.1 | B2: Label not in training data | O2: Frequency of label occurences precedes other label choices
A3: 1.2 | B3: Label occurs <5% of the time in training samples | O3: System boundary had a lot of trouble with fresh forage
A4: 1.3 | B4: Label occurs <10% of the time in training samples | O4: The reviewer noticed that classifying errors in FU was difficult with the given sentence description of the system was quite difficult.
A5: 1.4 | B5: Label occurs >90% of the time in training samples | O5: Sometimes the labeler would put the FU in the product description and not the FU labels
A6: 2.1 | B6: In Allocation, confused none with none required
A7: 2.2 | B7: In Allocation, chose economic when the humans chose a more specific label
A8: 3.1 | B8: In the system boundary, the authors of the study did not report an item the AI model wants to consider for completeness
A9: 3.2 | B9: In the system boundary, the AI model does not want to report an item the authors of the study did report for completeness
A10: 4 | B10: AI model likely incorrect
A11: 5 | B11: AI model has justifiable response
A12: 6 | B12: Unclear
A13: 7 | B13: RAG Added Misinformation
A14: 8.1 | B14: In FU, labeler only includes relative while AI model adds other categories
A15: 8.2 | B15: In FU, AI model confuses cold carcass weight, cold dressed carcass weight, and liveweight
A16: 9 | B16: Human authors/labelers appear to have made a mistake
